#VRML_SIM R2021a utf8
WorldInfo {
  basicTimeStep 16
  coordinateSystem "NUE"
}
Viewpoint {
  orientation -0.06379919198248729 0.9730107951040149 0.2217648658228673 2.6638462006592567
  position 0.6127434966740886 0.8344724663510323 -1.1859867838329465
}
TexturedBackground {
}
TexturedBackgroundLight {
}
Floor {
  size 1 1
}
DEF WALL_1 Solid {
  translation 0.5 0.05 0
  children [
    DEF WALL_SHAPE Shape {
      appearance PBRAppearance {
        baseColor 0.12549 0.368627 0.729412
        roughness 1
        metalness 0
      }
      geometry Box {
        size 0.02 0.1 0.98
      }
    }
  ]
  name "wall 1"
  boundingObject USE WALL_SHAPE
}
DEF WALL_2 Solid {
  translation -0.5 0.05 0
  children [
    USE WALL_SHAPE
  ]
  name "wall 2"
  boundingObject USE WALL_SHAPE
}
DEF WALL_3 Solid {
  translation 0 0.05 -0.5
  rotation 0 1 0 1.5708
  children [
    USE WALL_SHAPE
  ]
  name "wall 3"
  boundingObject USE WALL_SHAPE
}
DEF WALL_4 Solid {
  translation 0 0.05 0.5
  rotation 0 1 0 1.5708
  children [
    USE WALL_SHAPE
  ]
  name "wall 4"
  boundingObject USE WALL_SHAPE
}
Robot {
  translation -0.15408685203969405 0.03986048371854381 0.2329992179690275
  rotation -1.7055009742522723e-07 0.9999999999999852 -1.584738504111944e-08 -0.73669999396071
  children [
    DistanceSensor {
      translation 0.03 0.015 0.1
      rotation 0 1 0 -1.2708
      children [
        DEF DIST_SENSOR Shape {
          appearance PBRAppearance {
          }
          geometry Box {
            size 0.01 0.01 0.01
          }
        }
      ]
      name "ds_left"
      boundingObject USE DIST_SENSOR
    }
    DistanceSensor {
      translation -0.03 0.015 0.1
      rotation 0 0.9999999999999999 0 -1.8708
      children [
        DEF DIST_SENSOR Shape {
          appearance PBRAppearance {
          }
          geometry Box {
            size 0.01 0.01 0.01
          }
        }
      ]
      name "ds_right"
      boundingObject USE DIST_SENSOR
    }
    DEF BODY Shape {
      appearance PBRAppearance {
        baseColor 1 0 0
        roughness 1
        metalness 0
      }
      geometry Box {
        size 0.1 0.05 0.2
      }
    }
    DEF WHEEL1 HingeJoint {
      jointParameters DEF WHEEL2 HingeJointParameters {
        position 304.4797198928087
        anchor 0.06 0 0.05
      }
      device [
        RotationalMotor {
          name "wheel1"
        }
      ]
      endPoint DEF WHEEL1 Solid {
        translation 0.06 2.371832941386386e-08 0.049999993823121765
        rotation 0.7042233930468025 -0.7042259798085145 0.09019524404527407 2.9616896186784625
        children [
          DEF WHEEL Shape {
            appearance PBRAppearance {
              baseColor 0 0.666667 0
              roughness 1
              metalness 0
            }
            geometry Cylinder {
              height 0.02
              radius 0.04
            }
          }
        ]
        name "wheel1"
        boundingObject USE WHEEL
        physics Physics {
        }
        linearVelocity -0.026873900992243925 -5.53407239049261e-12 0.029627601898890455
        angularVelocity 0.7406897483656093 -1.3030326375041575e-08 0.6718472764107504
      }
    }
    DEF WHEEL2 HingeJoint {
      jointParameters HingeJointParameters {
        position 66.20806724892003
        anchor -0.06 0 0.05
      }
      device [
        RotationalMotor {
          name "wheel2"
        }
      ]
      endPoint DEF WHEEL2 Solid {
        translation -0.06 0 0.05
        rotation 0.704662929508095 -0.7046655178843175 -0.08304615392597137 3.3073041001947296
        children [
          USE WHEEL
        ]
        name "wheel2"
        boundingObject USE WHEEL
        physics Physics {
        }
        linearVelocity -0.026873887394731687 2.8060749841654015e-11 0.029627586908325478
        angularVelocity 0.7406897471689226 -1.3002294273188392e-08 0.671847275327576
      }
    }
    DEF WHEEL3 HingeJoint {
      jointParameters HingeJointParameters {
        position 155.80793198517918
        anchor 0.06 0 -0.05
      }
      device [
        RotationalMotor {
          name "wheel3"
        }
      ]
      endPoint DEF WHEEL3 Solid {
        translation 0.06 0 -0.05
        rotation 0.5106084947476681 -0.5106103703208414 -0.6917774315575306 4.35196145315192
        children [
          USE WHEEL
        ]
        name "solid(2)"
        boundingObject USE WHEEL
        physics Physics {
        }
        linearVelocity -0.026873887303789736 -3.171723465462633e-09 0.029627584787655953
        angularVelocity 0.7406897471025781 -1.295214311005896e-08 0.6718472752070042
      }
    }
    DEF WHEEL4 HingeJoint {
      jointParameters HingeJointParameters {
        position 66.20807164072407
        anchor -0.06 0 -0.05
      }
      device [
        RotationalMotor {
          name "wheel4"
        }
      ]
      endPoint DEF WHEEL4 Solid {
        translation -0.06 0 -0.05
        rotation 0.704662837697776 -0.7046654260736614 -0.08304771197416075 3.3073071949360293
        children [
          USE WHEEL
        ]
        name "solid(3)"
        boundingObject USE WHEEL
        physics Physics {
        }
        linearVelocity -0.02687388840042783 3.1490490770263718e-09 0.029627585996103014
        angularVelocity 0.740689747151124 -1.2997639985149586e-08 0.671847275347199
      }
    }
  ]
  boundingObject USE BODY
  physics Physics {
  }
  controller "four_wheels_collision_avoidance"
  linearVelocity -0.026873887046980932 -1.6032673522035109e-09 0.02962758551453492
  angularVelocity 5.9675183700019e-08 2.014523716808437e-08 -1.84070404813131e-08
}
FourWheelsRobot {
  hidden position_0_0 304.47971946387355
  hidden position_0_1 66.2080677308964
  hidden position_0_2 155.80793249807348
  hidden position_0_3 66.20807306470056
  hidden linearVelocity_0 -0.03681297064235313 -1.6022254638438965e-09 0.015646239830416197
  hidden angularVelocity_0 6.188441313748238e-08 2.0152050869082476e-08 8.2653042478572e-09
  hidden translation_3 0.06 2.371832676438147e-08 0.049999993823111585
  hidden rotation_3 0.7042233832961337 -0.70422597005781 0.09019539630759116 2.9616893166122966
  hidden linearVelocity_3 -0.03681299016920335 -7.233776288695255e-12 0.01564624886752599
  hidden angularVelocity_3 0.39115605411720983 -1.3032992129961689e-08 0.9203244033710813
  hidden rotation_4 0.704662919432502 -0.7046655078086875 -0.08304632491319303 3.307304439825609
  hidden linearVelocity_4 -0.03681297154207092 2.9763385287454225e-11 0.015646240950808837
  hidden angularVelocity_4 0.39115605348427074 -1.3004965312300963e-08 0.92032440188618
  hidden rotation_5 0.5106083635968139 -0.5106102391695055 -0.6917776251659519 4.351961715040074
  hidden linearVelocity_5 -0.03681297057068341 -3.1713825428239107e-09 0.015646239062255964
  hidden angularVelocity_5 0.39115605347451365 -1.2954817752403644e-08 0.9203244017488362
  hidden rotation_6 0.7046628079292845 -0.7046653963050604 -0.08304821714792311 3.307308198359319
  hidden linearVelocity_6 -0.036812972073454284 3.1487066910556424e-09 0.015646239700553864
  hidden angularVelocity_6 0.3911560534598917 -1.3000300446804952e-08 0.9203244018965403
  translation 0.048043762880226486 0.03986048371826996 -0.12806733648657595
  rotation -1.0650578631103908e-07 0.9999999999999938 -3.3963666601536434e-08 -1.1689089987961372
}
